Workbook
Name Segment_Jour: #N/A
Name Segment_JOUR1: #N/A
Name Segment_VEHICULE: #N/A
Name Segment_Véhicule: #N/A

Sheet UTILISATION TRACTEURS
I2: x

Sheet ACTIVITE BASES
F2: DASHBOARD SUIVI ACTIVITE TACTEURS ROUTIERS

Sheet Données Hebdo
A1: JOUR | B1: VEHICULE | C1: Durée | D1: Distance (km) | E1: Vitesse (km/h) | F1: Excés de vitesse | G1: Freinage | H1: Au ralenti | I1: Ralenti Durée | J1: Durée Utilisation
A2: Lundi | B2: BV666 | C2: 05:23:30 | D2: 33.82 | E2: 47 | F2: 0 | G2: 48 | H2: 0 | J2: =IFERROR(C2-I2,C2) -> 05:23:30 | K2: =I2+I6 -> #VALUE! | L2: 1.8669792
A3: Lundi | B3: BV778 | C3: 06:33:20 | D3: 48.73 | E3: 44 | F3: 0 | G3: 82 | H3: 0 | J3: =IFERROR(C3-I3,C3) -> 06:33:20 | K3: =I3+I7 -> #VALUE! | M3: =IFERROR(C3-I3,C3) -> 06:33:20
A4: Lundi | B4: BV793 | D4: 0 | E4: 0 | F4: 0 | G4: 0 | H4: 0 | J4: =IFERROR(C4-I4,C4) | K4: =I4+I8 -> #VALUE!
A5: Lundi | B5: BV794 | C5: 03:30:26 | D5: 36.02 | E5: 53 | F5: 0 | G5: 30 | H5: 2 | I5: 00:27:35 | J5: =IFERROR(C5-I5,C5) -> 0.12697917 | K5: =I5+I9 -> 0.026770833
A6: Lundi | B6: BVC74 | D6: 0 | E6: 0 | F6: 0 | G6: 0 | H6: 0 | J6: =IFERROR(C6-I6,C6) | K6: =I6+I10 -> #VALUE!
A7: Lundi | B7: BVC82 | C7: 00:00:12 | D7: 0 | E7: 0 | F7: 0 | G7: 0 | H7: 0 | J7: =IFERROR(C7-I7,C7) -> 00:00:12 | K7: =J7/24 -> 5.787037e-06
A8: Lundi | B8: BVT17 | C8: 04:17:52 | D8: 35.34 | E8: 58 | F8: 0 | G8: 0 | H8: 2 | I8: 00:56:00 | J8: =IFERROR(C8-I8,C8) -> 0.14018519 | K8: =J8/24 -> 0.0058410494
A9: Lundi | B9: BVT19 | C9: 00:10:51 | D9: 0.01 | E9: 0 | F9: 0 | G9: 0 | H9: 1 | I9: 00:10:58 | K9: =J9/24 -> 0
A10: Lundi | B10: BVT20 | C10: 00:55:59 | D10: 0.22 | E10: 15 | F10: 0 | G10: 0 | H10: 1 | I10: 00:26:15 | J10: =IFERROR(C10-I10,C10) -> 0.020648148 | K10: =J10/24 -> 0.00086033951
A11: Lundi | B11: BVT24 | C11: 10:29:08 | D11: 184.1 | E11: 64 | F11: 0 | G11: 25 | H11: 8 | I11: 02:27:07 | J11: =IFERROR(C11-I11,C11) -> 0.3347338 | K11: =J11/24 -> 0.013947242
A12: Lundi | B12: BVT25 | D12: 0 | E12: 0 | F12: 0 | G12: 0 | H12: 0 | J12: =IFERROR(C12-I12,C12) | K12: =J12/24 -> #VALUE!
A13: Lundi | B13: BVT26 | C13: 07:01:13 | D13: 140.44 | E13: 59 | F13: 0 | G13: 2 | H13: 5 | I13: 01:19:33 | J13: =IFERROR(C13-I13,C13) -> 0.23726852 | K13: =J13/24 -> 0.0098861883
A14: Lundi | B14: BVT31 | D14: 0 | E14: 0 | F14: 0 | G14: 0 | H14: 0 | J14: =IFERROR(C14-I14,C14) | K14: =J14/24 -> #VALUE!
A15: Lundi | B15: BVT37 | C15: 12:08:53 | D15: 297.53 | E15: 63 | F15: 0 | G15: 0 | H15: 7 | I15: 03:14:55 | J15: =IFERROR(C15-I15,C15) -> 0.37081019 | K15: =J15/24 -> 0.015450424
A16: Lundi | B16: BVT38 | C16: 00:43:56 | D16: 0.56 | E16: 10 | F16: 0 | G16: 0 | H16: 2 | I16: 00:29:40 | J16: =IFERROR(C16-I16,C16) -> 0.0099074074 | K16: =J16/24 -> 0.00041280864
A17: Lundi | B17: BVT50 | C17: 08:41:19 | D17: 248.39 | E17: 70 | F17: 0 | G17: 0 | H17: 0 | J17: =IFERROR(C17-I17,C17) -> 08:41:19 | K17: =J17/24 -> 0.015084394
A18: Lundi | B18: BVT51 | C18: 06:57:36 | D18: 28.48 | E18: 72 | F18: 1 | G18: 0 | H18: 3 | I18: 04:53:37 | J18: =IFERROR(C18-I18,C18) -> 0.086099537 | K18: =J18/24 -> 0.0035874807
A19: Lundi | B19: BVT58 | C19: 06:04:31 | D19: 33.86 | E19: 57 | F19: 0 | G19: 0 | H19: 3 | I19: 01:55:07 | J19: =IFERROR(C19-I19,C19) -> 0.17319444 | K19: =J19/24 -> 0.0072164352
A20: Lundi | B20: BVT59 | D20: 0 | E20: 0 | F20: 0 | G20: 0 | H20: 0 | J20: =IFERROR(C20-I20,C20) | K20: =J20/24 -> #VALUE!
A21: Lundi | B21: BVT60 | C21: 03:37:58 | D21: 37.94 | E21: 55 | F21: 0 | G21: 0 | H21: 3 | I21: 01:02:17 | J21: =IFERROR(C21-I21,C21) -> 0.10811343 | K21: =J21/24 -> 0.0045047261
A22: Lundi | B22: BVT61 | D22: 0 | E22: 0 | F22: 0 | G22: 0 | H22: 0 | J22: =IFERROR(C22-I22,C22) | K22: =J22/24 -> #VALUE!
A23: Lundi | B23: BVT62 | C23: 02:03:03 | D23: 1.56 | E23: 15 | F23: 0 | G23: 0 | H23: 3 | I23: 00:56:14 | J23: =IFERROR(C23-I23,C23) -> 0.046400463 | K23: =J23/24 -> 0.0019333526
A24: Lundi | B24: BVT65 | C24: 04:36:44 | D24: 13.61 | E24: 33 | F24: 0 | G24: 0 | H24: 6 | I24: 02:36:18 | J24: =IFERROR(C24-I24,C24) -> 0.083634259 | K24: =J24/24 -> 0.0034847608
A25: Lundi | B25: BVT77 | C25: 08:37:36 | D25: 211.22 | E25: 68 | F25: 0 | G25: 0 | H25: 4 | I25: 01:05:57 | J25: =IFERROR(C25-I25,C25) -> 0.31364583 | K25: =J25/24 -> 0.013068576
A26: Lundi | B26: BVT78 | C26: 07:54:50 | D26: 216.1 | E26: 77 | F26: 4 | G26: 1 | H26: 0 | J26: =IFERROR(C26-I26,C26) -> 07:54:50 | K26: =J26/24 -> 0.01373939
A27: Lundi | B27: BVT79 | C27: 08:05:47 | D27: 207.67 | E27: 69 | F27: 0 | G27: 13 | H27: 3 | I27: 00:37:28 | J27: =IFERROR(C27-I27,C27) -> 0.31133102 | K27: =J27/24 -> 0.012972126
A28: Lundi | B28: BVT80 | C28: 10:00:32 | D28: 181.52 | E28: 63 | F28: 0 | G28: 1 | H28: 7 | I28: 03:20:18 | J28: =IFERROR(C28-I28,C28) -> 0.27793981 | K28: =J28/24 -> 0.011580826
A29: Lundi | B29: BVT81 | D29: 0 | E29: 0 | F29: 0 | G29: 0 | H29: 0 | J29: =IFERROR(C29-I29,C29) | K29: =J29/24 -> #VALUE!
A30: Lundi | B30: BVT82 | C30: 10:59:18 | D30: 209.54 | E30: 62 | F30: 0 | G30: 2 | H30: 7 | I30: 03:24:50 | J30: =IFERROR(C30-I30,C30) -> 0.31560185 | K30: =J30/24 -> 0.013150077 | L30: 1.5118171
A31: Mardi | B31: BV666 | C31: 07:40:24 | D31: 67.18 | E31: 49 | F31: 0 | G31: 89 | H31: 0 | J31: =IFERROR(C31-I31,C31) -> 07:40:24 | K31: =J31/24 -> 0.013321759
A32: Mardi | B32: BV778 | C32: 08:07:56 | D32: 48.73 | E32: 34 | F32: 0 | G32: 76 | H32: 0 | J32: =IFERROR(C32-I32,C32) -> 08:07:56 | K32: =J32/24 -> 0.014118441
A33: Mardi | B33: BV793 | C33: 02:29:08 | D33: 16.23 | E33: 43 | F33: 0 | G33: 45 | H33: 2 | I33: 00:21:58 | J33: =IFERROR(C33-I33,C33) -> 0.088310185 | K33: =J33/24 -> 0.003679591
A34: Mardi | B34: BV794 | C34: 05:37:03 | D34: 56.05 | E34: 44 | F34: 0 | G34: 68 | H34: 0 | J34: =IFERROR(C34-I34,C34) -> 05:37:03 | K34: =J34/24 -> 0.0097526042
A35: Mardi | B35: BVC74 | D35: 0 | E35: 0 | F35: 0 | G35: 0 | H35: 0 | J35: =IFERROR(C35-I35,C35) | K35: =J35/24 -> #VALUE!
A36: Mardi | B36: BVC82 | D36: 0 | E36: 0 | F36: 0 | G36: 0 | H36: 0 | J36: =IFERROR(C36-I36,C36) | K36: =J36/24 -> #VALUE!
A37: Mardi | B37: BVT17 | C37: 09:33:44 | D37: 207.42 | E37: 62 | F37: 0 | G37: 0 | H37: 4 | I37: 02:25:13 | J37: =IFERROR(C37-I37,C37) -> 0.29758102 | K37: =J37/24 -> 0.012399209
A38: Mardi | B38: BVT19 | D38: 0 | E38: 0 | F38: 0 | G38: 0 | H38: 0 | J38: =IFERROR(C38-I38,C38) | K38: =J38/24 -> #VALUE!
A39: Mardi | B39: BVT20 | C39: 05:06:05 | D39: 0.8 | E39: 21 | F39: 0 | G39: 0 | H39: 3 | I39: 04:15:02 | J39: =IFERROR(C39-I39,C39) -> 0.035451389 | K39: =J39/24 -> 0.0014771412
A40: Mardi | B40: BVT24 | C40: 10:31:07 | D40: 166.06 | E40: 68 | F40: 0 | G40: 10 | H40: 5 | I40: 01:21:25 | J40: =IFERROR(C40-I40,C40) -> 0.38173611 | K40: =J40/24 -> 0.015905671
...

Sheet Graphe Hebdo
J1: Étiquettes de lignes | K1: Nombre de Base | M1: Jour | N1: (Tous) | S1: Jour | T1: (Tous) | AC1: Jour | AD1: (Tous)
J2: BVT39 | K2: 5
A3: Étiquettes de lignes | B3: Somme de Distance (km) | D3: Étiquettes de lignes | E3: Somme de Durée Utilisation | G3: Étiquettes de lignes | H3: Survitesse | J3: BVT81 | K3: 15 | M3: Étiquettes de lignes | N3: Nombre de Base | P3: Étiquettes de lignes | Q3: Somme de Durée | S3: Étiquettes de lignes | T3: Max de Durée Transit | V3: Étiquettes de lignes | W3: Durée Site | X3: Durée de Transit | Y3: Durée Arrêt C. On | AC3: Étiquettes de lignes | AD3: Durée Base de Départ | AE3: Durée de transit
A4: MV701 | B4: 15.642967 | D4: MV701 | G4: MV701 | J4: BVT82 | K4: 11 | M4: BASE RAZEL BAGANGTE | N4: 7 | P4: BASE RAZEL BAGANGTE | Q4: 4.5280903 | T4: 0 | V4: BASE RAZEL AEROPORT | W4: 2.2730671 | X4: 0.4246412 | Y4: 0 | AD4: 0 | AE4: 0
A5: Samedi | B5: 15.642967 | D5: Samedi | E5: 0.27855324 | G5: Samedi | J5: BV706 | K5: 3 | M5: BV706 | N5: 7 | P5: BV706 | Q5: 4.5280903 | S5: BV706 | T5: 0 | V5: BVT60 | W5: 0.57793981 | X5: 0.4246412 | Y5: 0 | AC5: BV706 | AD5: 0 | AE5: 0
A6: Total général | B6: 15.642967 | D6: Total général | E6: 0.27855324 | G6: Total général | J6: BV707 | K6: 3 | M6: Total général | N6: 7 | P6: Total général | Q6: 4.5280903 | S6: BASE RAZEL BAGANGTE - BASE RAZEL BAGANGTE | T6: 0.4590162 | V6: BVT77 | W6: 1.6951273 | X6: 0.080590278 | Y6: 0 | AD6: 0 | AE6: 0
J7: BV711 | K7: 4 | S7: BV706 | T7: 0.4590162 | V7: Total général | W7: 2.2730671 | X7: 0.4246412 | Y7: 0 | AC7: BASE RAZEL BAGANGTE - BASE RAZEL BAGANGTE | AD7: 0.254375 | AE7: 0.4590162
J8: BVC74 | K8: 7 | S8: Total général | T8: 0.4590162 | AC8: BV706 | AD8: 0.254375 | AE8: 0.4590162
J9: MV700 | K9: 6 | AC9: 06:48:50 à 17:49:49 | AD9: 0.254375 | AE9: 0.4590162
J10: MV701 | K10: 4 | AC10: Total général | AD10: 0.254375 | AE10: 0.4590162
J11: MV702 | K11: 3
J12: Total général | K12: 61

Sheet Feuil2
B1: BV666 KERAX 380 (RAZEL) | C1: 42394.237 | D1: BASE RAZEL PREFECTURE | E1: Lundi | F1: 42394.279 | G1: CARRIERE RAZEL NKOMETOU | H1: 22.341 | I1: 01h 01m 21s
B2: BV666 KERAX 380 (RAZEL) | C2: 42394.291 | D2: CARRIERE RAZEL NKOMETOU | E2: Lundi | F2: 42394.297 | G2: CARRIERE RAZEL NKOMETOU | H2: 0.191 | I2: 00h 09m 25s
B3: BV666 KERAX 380 (RAZEL) | C3: 42394.308 | D3: CARRIERE RAZEL NKOMETOU | E3: Lundi | F3: 42394.308 | G3: CARRIERE RAZEL NKOMETOU | H3: 0 | I3: 00h 00m 39s
B4: BV666 KERAX 380 (RAZEL) | C4: 42394.53 | D4: CARRIERE RAZEL NKOMETOU | E4: Lundi | F4: 42394.613 | G4: CARRIERE RAZEL NKOMETOU | H4: 45.789 | I4: 01h 58m 59s
B5: BV666 KERAX 380 (RAZEL) | C5: 42394.627 | D5: CARRIERE RAZEL NKOMETOU | E5: Lundi | F5: 42394.735 | G5: CARRIERE RAZEL NKOMETOU | H5: 46.157 | I5: 02h 35m 23s
B6: BV666 KERAX 380 (RAZEL) | C6: 42395.285 | D6: CARRIERE RAZEL NKOMETOU | E6: Mardi | F6: 42395.29 | G6: CARRIERE RAZEL NKOMETOU | H6: 0 | I6: 00h 07m 28s
B7: BV666 KERAX 380 (RAZEL) | C7: 42395.314 | D7: CARRIERE RAZEL NKOMETOU | E7: Mardi | F7: 42395.317 | G7: CARRIERE RAZEL NKOMETOU | H7: 0.354 | I7: 00h 03m 45s
B8: BV666 KERAX 380 (RAZEL) | C8: 42395.324 | D8: CARRIERE RAZEL NKOMETOU | E8: Mardi | F8: 42395.326 | G8: CARRIERE RAZEL NKOMETOU | H8: 0.025 | I8: 00h 03m 21s
B9: BV666 KERAX 380 (RAZEL) | C9: 42395.381 | D9: CARRIERE RAZEL NKOMETOU | E9: Mardi | F9: 42395.385 | G9: CARRIERE RAZEL NKOMETOU | H9: 0.01 | I9: 00h 04m 41s
B10: BV666 KERAX 380 (RAZEL) | C10: 42395.385 | D10: CARRIERE RAZEL NKOMETOU | E10: Mardi | F10: 42395.398 | G10: CARRIERE RAZEL NKOMETOU | H10: 0.429 | I10: 00h 17m 50s
B11: BV666 KERAX 380 (RAZEL) | C11: 42395.401 | D11: CARRIERE RAZEL NKOMETOU | E11: Mardi | F11: 42395.522 | G11: Unnamed Road, Yaoundé, Mfoundi, CAMEROON | H11: 30.347 | I11: 02h 54m 47s
B12: BV666 KERAX 380 (RAZEL) | C12: 42395.524 | D12: Unnamed Road, Yaoundé, Mfoundi, CAMEROON | E12: Mardi | F12: 42395.687 | G12: CARRIERE RAZEL NKOMETOU | H12: 38.497 | I12: 03h 54m 04s
... B23: BV666 KERAX 380 (RAZEL) | C23: 42398.307 | D23: CARRIERE RAZEL NKOMETOU | E23: Vendredi | F23: 42398.702 | G23: CARRIERE RAZEL NKOMETOU | H23: 137.352 | I23: 09h 28m 55s
B24: BV778 KERAX 380 (RAZEL) | C24: 42394.241 | E24: Lundi | F24: 42394.254 | G24: N 1, Yaounde, Central, CAMEROON | H24: 9.757 | I24: 00h 19m 08s
B25: BV778 KERAX 380 (RAZEL) | C25: 42394.261 | D25: N 1, Yaounde, Central, CAMEROON | E25: Lundi | F25: 42394.273 | G25: 0.8km SW of CARRIERE RAZEL NKOMETOU - MEYOS, OBALA, CAMEROON | H25: 11.608 | I25: 00h 16m 15s
B26: BV778 KERAX 380 (RAZEL) | C26: 42394.275 | D26: 0.8km SW of CARRIERE RAZEL NKOMETOU - MEYOS, OBALA, CAMEROON | E26: Lundi | F26: 42394.277 | G26: CARRIERE RAZEL NKOMETOU | H26: 0.993 | I26: 00h 02m 31s
B27: BV778 KERAX 380 (RAZEL) | C27: 42394.293 | D27: CARRIERE RAZEL NKOMETOU | E27: Lundi | F27: 42394.391 | G27: CARRIERE RAZEL NKOMETOU | H27: 46.124 | I27: 02h 21m 47s
B28: BV778 KERAX 380 (RAZEL) | C28: 42394.394 | D28: CARRIERE RAZEL NKOMETOU | E28: Lundi | F28: 42394.485 | G28: CARRIERE RAZEL NKOMETOU | H28: 46.275 | I28: 02h 10m 23s
B29: BV778 KERAX 380 (RAZEL) | C29: 42394.488 | D29: CARRIERE RAZEL NKOMETOU | E29: Lundi | F29: 42394.501 | G29: CARRIERE RAZEL NKOMETOU | H29: 1.071 | I29: 00h 18m 43s
B30: BV778 KERAX 380 (RAZEL) | C30: 42394.514 | D30: CARRIERE RAZEL NKOMETOU | E30: Lundi | F30: 42394.627 | G30: CARRIERE RAZEL NKOMETOU | H30: 53.131 | I30: 02h 42m 57s
B31: BV778 KERAX 380 (RAZEL) | C31: 42394.631 | D31: CARRIERE RAZEL NKOMETOU | E31: Lundi | F31: 42394.642 | G31: CARRIERE RAZEL NKOMETOU | H31: 0.791 | I31: 00h 15m 14s
B32: BV778 KERAX 380 (RAZEL) | C32: 42394.645 | D32: CARRIERE RAZEL NKOMETOU | E32: Lundi | F32: 42394.65 | G32: CARRIERE RAZEL NKOMETOU | H32: 0.559 | I32: 00h 07m 38s
B33: BV778 KERAX 380 (RAZEL) | C33: 42394.655 | D33: CARRIERE RAZEL NKOMETOU | E33: Lundi | F33: 42394.738 | G33: CARRIERE RAZEL NKOMETOU | H33: 44.594 | I33: 02h 00m 33s
B34: BV778 KERAX 380 (RAZEL) | C34: 42395.287 | E34: Mardi | F34: 42395.292 | G34: CARRIERE RAZEL NKOMETOU | H34: 0 | I34: 00h 07m 56s
B35: BV778 KERAX 380 (RAZEL) | C35: 42395.319 | D35: CARRIERE RAZEL NKOMETOU | E35: Mardi | F35: 42395.391 | G35: CARRIERE RAZEL NKOMETOU | H35: 42.838 | I35: 01h 43m 54s
B36: BV778 KERAX 380 (RAZEL) | C36: 42395.398 | D36: CARRIERE RAZEL NKOMETOU | E36: Mardi | F36: 42395.489 | G36: CARRIERE RAZEL NKOMETOU | H36: 45.498 | I36: 02h 11m 26s
B37: BV778 KERAX 380 (RAZEL) | C37: 42395.502 | D37: CARRIERE RAZEL NKOMETOU | E37: Mardi | F37: 42395.519 | G37: CARRIERE RAZEL NKOMETOU | H37: 1.01 | I37: 00h 24m 03s
B38: BV778 KERAX 380 (RAZEL) | C38: 42395.545 | D38: CARRIERE RAZEL NKOMETOU | E38: Mardi | F38: 42395.58 | G38: 0.1km SW of Comité Internationale de La CR - Rue Zogo Fouda Ngono, YAOUNDE, YAOUNDE 1, CAMEROON | H38: 22.511 | I38: 00h 51m 15s
B39: BV778 KERAX 380 (RAZEL) | C39: 42395.581 | D39: 0.1km SW of Comité Internationale de La CR - Rue Zogo Fouda Ngono, YAOUNDE, YAOUNDE 1, CAMEROON | E39: Mardi | F39: 42395.61 | G39: CARRIERE RAZEL NKOMETOU | H39: 22.473 | I39: 00h 41m 12s
B40: BV778 KERAX 380 (RAZEL) | C40: 42395.614 | D40: CARRIERE RAZEL NKOMETOU | E40: Mardi | F40: 42395.624 | G40: CARRIERE RAZEL NKOMETOU | H40: 0.797 | I40: 00h 13m 52s
B41: BV778 KERAX 380 (RAZEL) | C41: 42395.627 | D41: CARRIERE RAZEL NKOMETOU | E41: Mardi | F41: 42395.731 | G41: CARRIERE RAZEL NKOMETOU | H41: 47.452 | I41: 02h 28m 57s
B42: BV778 KERAX 380 (RAZEL) | C42: 42396.287 | D42: CARRIERE RAZEL NKOMETOU | E42: Mercredi | F42: 42396.497 | G42: BASE RAZEL PREFECTURE | H42: 99.42 | I42: 05h 03m 22s
B43: BV778 KERAX 380 (RAZEL) | C43: 42396.505 | D43: BASE RAZEL PREFECTURE | E43: Mercredi | F43: 42396.566 | G43: CARRIERE RAZEL NKOMETOU | H43: 31.488 | I43: 01h 28m 39s
B44: BV778 KERAX 380 (RAZEL) | C44: 42396.601 | D44: CARRIERE RAZEL NKOMETOU | E44: Mercredi | F44: 42396.744 | G44: BASE RAZEL PREFECTURE | H44: 53.881 | I44: 03h 26m 46s
B45: BV778 KERAX 380 (RAZEL) | C45: 42397.268 | E45: Jeudi | F45: 42397.306 | G45: CARRIERE RAZEL NKOMETOU | H45: 22.59 | I45: 00h 54m 57s
B46: BV778 KERAX 380 (RAZEL) | C46: 42397.311 | D46: CARRIERE RAZEL NKOMETOU | E46: Jeudi | F46: 42397.513 | G46: CARRIERE RAZEL NKOMETOU | H46: 90.493 | I46: 04h 51m 11s
B47: BV778 KERAX 380 (RAZEL) | C47: 42397.52 | D47: CARRIERE RAZEL NKOMETOU | E47: Jeudi | F47: 42397.668 | G47: CARRIERE RAZEL NKOMETOU | H47: 61.745 | I47: 03h 33m 15s
B48: BV778 KERAX 380 (RAZEL) | C48: 42397.67 | D48: CARRIERE RAZEL NKOMETOU | E48: Jeudi | F48: 42397.731 | G48: CARRIERE RAZEL NKOMETOU | H48: 30.693 | I48: 01h 27m 19s
B49: BV778 KERAX 380 (RAZEL) | C49: 42397.736 | D49: CARRIERE RAZEL NKOMETOU | E49: Jeudi | F49: 42397.74 | G49: CARRIERE RAZEL NKOMETOU | H49: 0.532 | I49: 00h 06m 26s
B50: BV778 KERAX 380 (RAZEL) | C50: 42398.278 | E50: Vendredi | F50: 42398.358 | G50: CARRIERE RAZEL NKOMETOU | H50: 30.17 | I50: 01h 54m 41s
...

Sheet Feuil1
A1: Véhicule | B1: Base | C1: Date Entrée | D1: Date Sortie | E1: Durée | F1: Jour | G1: Durée Transit | H1: Transit | I1: Arrêt C. On | J1: Heures de Transit | K1: Heure Entrée | L1: Durée transit | M1: Durée Base Départ | N1: Transit
A2: BV706 | B2: BASE RAZEL BAGANGTE | C2: 2016-05-30 00:42:32 | D2: 2016-05-30 06:48:50 | E2: =IFERROR(D2-C2, "") -> 0.254375 | F2: Lundi | G2: =IF(A2=A1, C2-D1, "") | H2: =IF(A2=A1, B1&" - "&B2, "") | I2: =IF(F1='Données Hebdo'!A2, VLOOKUP(Feuil1!A2, 'Données Hebdo'!B:J, 8, FALSE), "") | J2: =IF(A2=A3, RIGHT(D2, 8)&" à "&RIGHT(C3, 8), "") -> 06:48:50 à 17:49:49 | K2: =IF(A2=A3, C3, "") -> 2016-05-30 17:49:49 | L2: =IF(A2=A3, G3, "") -> 0.4590162 | M2: =IF(A2=A3, E2, "") -> 0.254375 | N2: =IF(A2=A3, H3, "") -> BASE RAZEL BAGANGTE - BASE RAZEL BAGANGTE
A3: BV706 | B3: BASE RAZEL BAGANGTE | C3: 2016-05-30 17:49:49 | D3: 2016-05-31 07:46:41 | E3: =IFERROR(D3-C3, "") -> 0.58115741 | F3: Lundi | G3: =IF(A3=A2, C3-D2, "") -> 0.4590162 | H3: =IF(A3=A2, B2&" - "&B3, "") -> BASE RAZEL BAGANGTE - BASE RAZEL BAGANGTE | I3: =IF(F2='Données Hebdo'!A3, VLOOKUP(Feuil1!A3, 'Données Hebdo'!B:J, 8, FALSE), "") -> 0 | J3: =IF(A3=A4, RIGHT(D3, 8)&" à "&RIGHT(C4, 8), "") | K3: =IF(A3=A4, C4, "") | L3: =IF(A3=A4, G4, "") | M3: =IF(A3=A4, E3, "") | N3: =IF(A3=A4, H4, "")
A4: BV707 | B4: BASE RAZEL BAGANGTE | C4: 2016-05-30 00:52:00 | D4: 2016-05-30 06:48:51 | E4: =IFERROR(D4-C4, "") -> 0.2478125 | F4: Lundi | G4: =IF(A4=A3, C4-D3, "") | H4: =IF(A4=A3, B3&" - "&B4, "") | I4: =IF(F3='Données Hebdo'!A4, VLOOKUP(Feuil1!A4, 'Données Hebdo'!B:J, 8, FALSE), "") -> 0 | J4: =IF(A4=A5, RIGHT(D4, 8)&" à "&RIGHT(C5, 8), "") -> 06:48:51 à 17:47:42 | K4: =IF(A4=A5, C5, "") -> 2016-05-30 17:47:42 | L4: =IF(A4=A5, G5, "") -> 0.45753472 | M4: =IF(A4=A5, E4, "") -> 0.2478125 | N4: =IF(A4=A5, H5, "") -> BASE RAZEL BAGANGTE - BASE RAZEL BAGANGTE
A5: BV707 | B5: BASE RAZEL BAGANGTE | C5: 2016-05-30 17:47:42 | D5: 2016-05-31 07:34:18 | E5: =IFERROR(D5-C5, "") -> 0.57402778 | F5: Lundi | G5: =IF(A5=A4, C5-D4, "") -> 0.45753472 | H5: =IF(A5=A4, B4&" - "&B5, "") -> BASE RAZEL BAGANGTE - BASE RAZEL BAGANGTE | I5: =IF(F4='Données Hebdo'!A5, VLOOKUP(Feuil1!A5, 'Données Hebdo'!B:J, 8, FALSE), "") -> 0 | J5: =IF(A5=A6, RIGHT(D5, 8)&" à "&RIGHT(C6, 8), "") | K5: =IF(A5=A6, C6, "") | L5: =IF(A5=A6, G6, "") | M5: =IF(A5=A6, E5, "") | N5: =IF(A5=A6, H6, "")
A6: BV711 | B6: BASE RAZEL BAGANGTE | C6: 2016-05-30 00:32:52 | D6: 2016-05-30 08:21:54 | E6: =IFERROR(D6-C6, "") -> 0.32571759 | F6: Lundi | G6: =IF(A6=A5, C6-D5, "") | H6: =IF(A6=A5, B5&" - "&B6, "") | I6: =IF(F5='Données Hebdo'!A6, VLOOKUP(Feuil1!A6, 'Données Hebdo'!B:J, 8, FALSE), "") -> 0 | J6: =IF(A6=A7, RIGHT(D6, 8)&" à "&RIGHT(C7, 8), "") -> 08:21:54 à 08:40:54 | K6: =IF(A6=A7, C7, "") -> 2016-05-30 08:40:54 | L6: =IF(A6=A7, G7, "") -> 0.013194444 | M6: =IF(A6=A7, E6, "") -> 0.32571759 | N6: =IF(A6=A7, H7, "") -> BASE RAZEL BAGANGTE - CARRIERE RAZEL BAGANGTE
A7: BV711 | B7: CARRIERE RAZEL BAGANGTE | C7: 2016-05-30 08:40:54 | D7: 2016-05-30 08:50:30 | E7: =IFERROR(D7-C7, "") -> 0.0066666667 | F7: Lundi | G7: =IF(A7=A6, C7-D6, "") -> 0.013194444 | H7: =IF(A7=A6, B6&" - "&B7, "") -> BASE RAZEL BAGANGTE - CARRIERE RAZEL BAGANGTE | I7: =IF(F6='Données Hebdo'!A7, VLOOKUP(Feuil1!A7, 'Données Hebdo'!B:J, 8, FALSE), "") -> 0 | J7: =IF(A7=A8, RIGHT(D7, 8)&" à "&RIGHT(C8, 8), "") -> 08:50:30 à 08:53:30 | K7: =IF(A7=A8, C8, "") -> 2016-05-30 08:53:30 | L7: =IF(A7=A8, G8, "") -> 0.0020833333 | M7: =IF(A7=A8, E7, "") -> 0.0066666667 | N7: =IF(A7=A8, H8, "") -> CARRIERE RAZEL BAGANGTE - CARRIERE RAZEL BAGANGTE
A8: BV711 | B8: CARRIERE RAZEL BAGANGTE | C8: 2016-05-30 08:53:30 | D8: 2016-05-30 09:02:30 | E8: =IFERROR(D8-C8, "") -> 0.00625 | F8: Lundi | G8: =IF(A8=A7, C8-D7, "") -> 0.0020833333 | H8: =IF(A8=A7, B7&" - "&B8, "") -> CARRIERE RAZEL BAGANGTE - CARRIERE RAZEL BAGANGTE | I8: =IF(F7='Données Hebdo'!A8, VLOOKUP(Feuil1!A8, 'Données Hebdo'!B:J, 8, FALSE), "") -> 0 | J8: =IF(A8=A9, RIGHT(D8, 8)&" à "&RIGHT(C9, 8), "") | K8: =IF(A8=A9, C9, "") | L8: =IF(A8=A9, G9, "") | M8: =IF(A8=A9, E8, "") | N8: =IF(A8=A9, H9, "")
A9: BVC74 | B9: BASE RAZEL BAGANGTE | C9: 2016-05-30 00:31:14 | D9: 2016-05-30 08:26:58 | E9: =IFERROR(D9-C9, "") -> 0.33037037 | F9: Lundi | G9: =IF(A9=A8, C9-D8, "") | H9: =IF(A9=A8, B8&" - "&B9, "") | I9: =IF(F8='Données Hebdo'!A9, VLOOKUP(Feuil1!A9, 'Données Hebdo'!B:J, 8, FALSE), "") | J9: =IF(A9=A10, RIGHT(D9, 8)&" à "&RIGHT(C10, 8), "") -> 08:26:58 à 11:40:58 | K9: =IF(A9=A10, C10, "") -> 2016-05-30 11:40:58 | L9: =IF(A9=A10, G10, "") -> 0.13472222 | M9: =IF(A9=A10, E9, "") -> 0.33037037 | N9: =IF(A9=A10, H10, "") -> BASE RAZEL BAGANGTE - CARRIERE RAZEL BAGANGTE
A10: BVC74 | B10: CARRIERE RAZEL BAGANGTE | C10: 2016-05-30 11:40:58 | D10: 2016-05-30 11:54:59 | E10: =IFERROR(D10-C10, "") -> 0.0097337963 | F10: Lundi | G10: =IF(A10=A9, C10-D9, "") -> 0.13472222 | H10: =IF(A10=A9, B9&" - "&B10, "") -> BASE RAZEL BAGANGTE - CARRIERE RAZEL BAGANGTE | I10: =IF(F9='Données Hebdo'!A10, VLOOKUP(Feuil1!A10, 'Données Hebdo'!B:J, 8, FALSE), "") | J10: =IF(A10=A11, RIGHT(D10, 8)&" à "&RIGHT(C11, 8), "") -> 11:54:59 à 13:25:59 | K10: =IF(A10=A11, C11, "") -> 2016-05-30 13:25:59 | L10: =IF(A10=A11, G11, "") -> 0.063194444 | M10: =IF(A10=A11, E10, "") -> 0.0097337963 | N10: =IF(A10=A11, H11, "") -> CARRIERE RAZEL BAGANGTE - BASE RAZEL BAGANGTE
A11: BVC74 | B11: BASE RAZEL BAGANGTE | C11: 2016-05-30 13:25:59 | D11: 2016-05-31 07:34:08 | E11: =IFERROR(D11-C11, "") -> 0.75565972 | F11: Lundi | G11: =IF(A11=A10, C11-D10, "") -> 0.063194444 | H11: =IF(A11=A10, B10&" - "&B11, "") -> CARRIERE RAZEL BAGANGTE - BASE RAZEL BAGANGTE | I11: =IF(F10='Données Hebdo'!A11, VLOOKUP(Feuil1!A11, 'Données Hebdo'!B:J, 8, FALSE), "") | J11: =IF(A11=A12, RIGHT(D11, 8)&" à "&RIGHT(C12, 8), "") | K11: =IF(A11=A12, C12, "") | L11: =IF(A11=A12, G12, "") | M11: =IF(A11=A12, E11, "") | N11: =IF(A11=A12, H12, "")
A12: BVT39 | B12: BASE RAZEL PREFECTURE | C12: 2016-05-30 06:57:11 | D12: 2016-05-30 08:35:30 | E12: =IFERROR(D12-C12, "") -> 0.068275463 | F12: Lundi | G12: =IF(A12=A11, C12-D11, "") | H12: =IF(A12=A11, B11&" - "&B12, "") | I12: =IF(F11='Données Hebdo'!A12, VLOOKUP(Feuil1!A12, 'Données Hebdo'!B:J, 8, FALSE), "") -> 0 | J12: =IF(A12=A13, RIGHT(D12, 8)&" à "&RIGHT(C13, 8), "") -> 08:35:30 à 08:36:30 | K12: =IF(A12=A13, C13, "") -> 2016-05-30 08:36:30 | L12: =IF(A12=A13, G13, "") -> 0.00069444444 | M12: =IF(A12=A13, E12, "") -> 0.068275463 | N12: =IF(A12=A13, H13, "") -> BASE RAZEL PREFECTURE - BASE RAZEL PREFECTURE
A13: BVT39 | B13: BASE RAZEL PREFECTURE | C13: 2016-05-30 08:36:30 | D13: 2016-05-30 16:52:48 | E13: =IFERROR(D13-C13, "") -> 0.34465278 | F13: Lundi | G13: =IF(A13=A12, C13-D12, "") -> 0.00069444444 | H13: =IF(A13=A12, B12&" - "&B13, "") -> BASE RAZEL PREFECTURE - BASE RAZEL PREFECTURE | I13: =IF(F12='Données Hebdo'!A13, VLOOKUP(Feuil1!A13, 'Données Hebdo'!B:J, 8, FALSE), "") -> 0 | J13: =IF(A13=A14, RIGHT(D13, 8)&" à "&RIGHT(C14, 8), "") | K13: =IF(A13=A14, C14, "") | L13: =IF(A13=A14, G14, "") | M13: =IF(A13=A14, E13, "") | N13: =IF(A13=A14, H14, "")
... A37: MV701 | B37: CARRIERE RAZEL NKOMETOU | C37: 2016-05-30 09:09:27 | D37: 2016-05-30 09:52:27 | E37: =IFERROR(D37-C37, "") -> 0.029861111 | F37: Lundi | G37: =IF(A37=A36, C37-D36, "") | H37: =IF(A37=A36, B36&" - "&B37, "") | I37: =IF(F36='Données Hebdo'!A37, VLOOKUP(Feuil1!A37, 'Données Hebdo'!B:J, 8, FALSE), "") -> 0 | J37: =IF(A37=A38, RIGHT(D37, 8)&" à "&RIGHT(C38, 8), "") -> 09:52:27 à 11:32:27 | K37: =IF(A37=A38, C38, "") -> 2016-05-30 11:32:27 | L37: =IF(A37=A38, G38, "") -> 0.069444444 | M37: =IF(A37=A38, E37, "") -> 0.029861111 | N37: =IF(A37=A38, H38, "") -> CARRIERE RAZEL NKOMETOU - BASE RAZEL PADY 2
A38: MV701 | B38: BASE RAZEL PADY 2 | C38: 2016-05-30 11:32:27 | D38: 2016-05-30 11:42:39 | E38: =IFERROR(D38-C38, "") -> 0.0070833333 | F38: Lundi | G38: =IF(A38=A37, C38-D37, "") -> 0.069444444 | H38: =IF(A38=A37, B37&" - "&B38, "") -> CARRIERE RAZEL NKOMETOU - BASE RAZEL PADY 2 | I38: =IF(F37='Données Hebdo'!A37, VLOOKUP(Feuil1!A38, 'Données Hebdo'!B:J, 8, FALSE), "") | J38: =IF(A38=A39, RIGHT(D38, 8)&" à "&RIGHT(C39, 8), "") -> 11:42:39 à 12:50:41 | K38: =IF(A38=A39, C39, "") -> 2016-05-30 12:50:41 | L38: =IF(A38=A39, G39, "") -> 0.04724537 | M38: =IF(A38=A39, E38, "") -> 0.0070833333 | N38: =IF(A38=A39, H39, "") -> BASE RAZEL PADY 2 - CARRIERE RAZEL NKOMETOU
A39: MV701 | B39: CARRIERE RAZEL NKOMETOU | C39: 2016-05-30 12:50:41 | D39: 2016-05-30 13:38:41 | E39: =IFERROR(D39-C39, "") -> 0.033333333 | F39: Lundi | G39: =IF(A39=A38, C39-D38, "") -> 0.04724537 | H39: =IF(A39=A38, B38&" - "&B39, "") -> BASE RAZEL PADY 2 - CARRIERE RAZEL NKOMETOU | I39: =IF(F38='Données Hebdo'!A38, VLOOKUP(Feuil1!A39, 'Données Hebdo'!B:J, 8, FALSE), "") | J39: =IF(A39=A40, RIGHT(D39, 8)&" à "&RIGHT(C40, 8), "") -> 13:38:41 à 15:41:41 | K39: =IF(A39=A40, C40, "") -> 2016-05-30 15:41:41 | L39: =IF(A39=A40, G40, "") -> 0.085416667 | M39: =IF(A39=A40, E39, "") -> 0.033333333 | N39: =IF(A39=A40, H40, "") -> CARRIERE RAZEL NKOMETOU - CARRIERE RAZEL NKOMETOU
A40: MV701 | B40: CARRIERE RAZEL NKOMETOU | C40: 2016-05-30 15:41:41 | D40: 2016-05-30 16:28:41 | E40: =IFERROR(D40-C40, "") -> 0.032638889 | F40: Lundi | G40: =IF(A40=A39, C40-D39, "") -> 0.085416667 | H40: =IF(A40=A39, B39&" - "&B40, "") -> CARRIERE RAZEL NKOMETOU - CARRIERE RAZEL NKOMETOU | I40: =IF(F39='Données Hebdo'!A39, VLOOKUP(Feuil1!A40, 'Données Hebdo'!B:J, 8, FALSE), "") | J40: =IF(A40=A41, RIGHT(D40, 8)&" à "&RIGHT(C41, 8), "") | K40: =IF(A40=A41, C41, "") | L40: =IF(A40=A41, G41, "") | M40: =IF(A40=A41, E40, "") | N40: =IF(A40=A41, H41, "")
A41: MV702 | B41: BASE RAZEL PADY 2 | C41: 2016-05-30 07:03:58 | D41: 2016-05-30 07:20:56 | E41: =IFERROR(D41-C41, "") -> 0.011782407 | F41: Lundi | G41: =IF(A41=A40, C41-D40, "") | H41: =IF(A41=A40, B40&" - "&B41, "") | I41: =IF(F40='Données Hebdo'!A40, VLOOKUP(Feuil1!A41, 'Données Hebdo'!B:J, 8, FALSE), "") | J41: =IF(A41=A42, RIGHT(D41, 8)&" à "&RIGHT(C42, 8), "") -> 07:20:56 à 08:14:56 | K41: =IF(A41=A42, C42, "") -> 2016-05-30 08:14:56 | L41: =IF(A41=A42, G42, "") -> 0.0375 | M41: =IF(A41=A42, E41, "") -> 0.011782407 | N41: =IF(A41=A42, H42, "") -> BASE RAZEL PADY 2 - CARRIERE RAZEL NKOMETOU
A42: MV702 | B42: CARRIERE RAZEL NKOMETOU | C42: 2016-05-30 08:14:56 | D42: 2016-05-30 08:45:00 | E42: =IFERROR(D42-C42, "") -> 0.02087963 | F42: Lundi | G42: =IF(A42=A41, C42-D41, "") -> 0.0375 | H42: =IF(A42=A41, B41&" - "&B42, "") -> BASE RAZEL PADY 2 - CARRIERE RAZEL NKOMETOU | I42: =IF(F41='Données Hebdo'!A41, VLOOKUP(Feuil1!A42, 'Données Hebdo'!B:J, 8, FALSE), "") | J42: =IF(A42=A43, RIGHT(D42, 8)&" à "&RIGHT(C43, 8), "") -> 08:45:00 à 10:04:00 | K42: =IF(A42=A43, C43, "") -> 2016-05-30 10:04:00 | L42: =IF(A42=A43, G43, "") -> 0.054861111 | M42: =IF(A42=A43, E42, "") -> 0.02087963 | N42: =IF(A42=A43, H43, "") -> CARRIERE RAZEL NKOMETOU - BASE RAZEL PADY 2
A43: MV702 | B43: BASE RAZEL PADY 2 | C43: 2016-05-30 10:04:00 | D43: 2016-05-30 17:02:16 | E43: =IFERROR(D43-C43, "") -> 0.29046296 | F43: Lundi | G43: =IF(A43=A42, C43-D42, "") -> 0.054861111 | H43: =IF(A43=A42, B42&" - "&B43, "") -> CARRIERE RAZEL NKOMETOU - BASE RAZEL PADY 2 | I43: =IF(F42='Données Hebdo'!A42, VLOOKUP(Feuil1!A43, 'Données Hebdo'!B:J, 8, FALSE), "") | J43: =IF(A43=A44, RIGHT(D43, 8)&" à "&RIGHT(C44, 8), "") | K43: =IF(A43=A44, C44, "") | L43: =IF(A43=A44, G44, "") | M43: =IF(A43=A44, E43, "") | N43: =IF(A43=A44, H44, "")
A44: BV706 | B44: BASE RAZEL BAGANGTE | C44: 2016-05-31 17:34:50 | D44: 2016-06-01 06:50:54 | E44: =IFERROR(D44-C44, "") -> 0.55282407 | F44: Lundi | G44: =IF(A44=A43, C44-D43, "") | H44: =IF(A44=A43, B43&" - "&B44, "") | I44: =IF(F43='Données Hebdo'!A43, VLOOKUP(Feuil1!A44, 'Données Hebdo'!B:J, 8, FALSE), "") | J44: =IF(A44=A45, RIGHT(D44, 8)&" à "&RIGHT(C45, 8), "") | K44: =IF(A44=A45, C45, "") | L44: =IF(A44=A45, G45, "") | M44: =IF(A44=A45, E44, "") | N44: =IF(A44=A45, H45, "")
A45: BV707 | B45: BASE RAZEL BAGANGTE | C45: 2016-05-31 17:55:05 | D45: 2016-06-01 07:36:18 | E45: =IFERROR(D45-C45, "") -> 0.57028935 | F45: Lundi | G45: =IF(A45=A44, C45-D44, "") | H45: =IF(A45=A44, B44&" - "&B45, "") | I45: =IF(F44='Données Hebdo'!A44, VLOOKUP(Feuil1!A45, 'Données Hebdo'!B:J, 8, FALSE), "") | J45: =IF(A45=A46, RIGHT(D45, 8)&" à "&RIGHT(C46, 8), "") | K45: =IF(A45=A46, C46, "") | L45: =IF(A45=A46, G46, "") | M45: =IF(A45=A46, E45, "") | N45: =IF(A45=A46, H46, "")
A46: BV711 | B46: BASE RAZEL BAGANGTE | C46: 2016-05-31 17:50:45 | D46: 2016-06-01 08:51:27 | E46: =IFERROR(D46-C46, "") -> 0.62548611 | F46: Lundi | G46: =IF(A46=A45, C46-D45, "") | H46: =IF(A46=A45, B45&" - "&B46, "") | I46: =IF(F45='Données Hebdo'!A45, VLOOKUP(Feuil1!A46, 'Données Hebdo'!B:J, 8, FALSE), "") | J46: =IF(A46=A47, RIGHT(D46, 8)&" à "&RIGHT(C47, 8), "") | K46: =IF(A46=A47, C47, "") | L46: =IF(A46=A47, G47, "") | M46: =IF(A46=A47, E46, "") | N46: =IF(A46=A47, H47, "")
A47: BVC74 | B47: CARRIERE RAZEL BAGANGTE | C47: 2016-05-31 08:51:59 | D47: 2016-05-31 08:53:59 | E47: =IFERROR(D47-C47, "") -> 0.0013888889 | F47: Lundi | G47: =IF(A47=A46, C47-D46, "") | H47: =IF(A47=A46, B46&" - "&B47, "") | I47: =IF(F46='Données Hebdo'!A46, VLOOKUP(Feuil1!A47, 'Données Hebdo'!B:J, 8, FALSE), "") | J47: =IF(A47=A48, RIGHT(D47, 8)&" à "&RIGHT(C48, 8), "") -> 08:53:59 à 12:13:58 | K47: =IF(A47=A48, C48, "") -> 2016-05-31 12:13:58 | L47: =IF(A47=A48, G48, "") -> 0.13887731 | M47: =IF(A47=A48, E47, "") -> 0.0013888889 | N47: =IF(A47=A48, H48, "") -> CARRIERE RAZEL BAGANGTE - CARRIERE RAZEL BAGANGTE
A48: BVC74 | B48: CARRIERE RAZEL BAGANGTE | C48: 2016-05-31 12:13:58 | D48: 2016-05-31 12:28:58 | E48: =IFERROR(D48-C48, "") -> 0.010416667 | F48: Lundi | G48: =IF(A48=A47, C48-D47, "") -> 0.13887731 | H48: =IF(A48=A47, B47&" - "&B48, "") -> CARRIERE RAZEL BAGANGTE - CARRIERE RAZEL BAGANGTE | I48: =IF(F47='Données Hebdo'!A47, VLOOKUP(Feuil1!A48, 'Données Hebdo'!B:J, 8, FALSE), "") | J48: =IF(A48=A49, RIGHT(D48, 8)&" à "&RIGHT(C49, 8), "") -> 12:28:58 à 13:23:58 | K48: =IF(A48=A49, C49, "") -> 2016-05-31 13:23:58 | L48: =IF(A48=A49, G49, "") -> 0.038194444 | M48: =IF(A48=A49, E48, "") -> 0.010416667 | N48: =IF(A48=A49, H49, "") -> CARRIERE RAZEL BAGANGTE - BASE RAZEL BAGANGTE
A49: BVC74 | B49: BASE RAZEL BAGANGTE | C49: 2016-05-31 13:23:58 | D49: 2016-05-31 16:25:08 | E49: =IFERROR(D49-C49, "") -> 0.12581019 | F49: Lundi | G49: =IF(A49=A48, C49-D48, "") -> 0.038194444 | H49: =IF(A49=A48, B48&" - "&B49, "") -> CARRIERE RAZEL BAGANGTE - BASE RAZEL BAGANGTE | I49: =IF(F48='Données Hebdo'!A48, VLOOKUP(Feuil1!A49, 'Données Hebdo'!B:J, 8, FALSE), "") | J49: =IF(A49=A50, RIGHT(D49, 8)&" à "&RIGHT(C50, 8), "") -> 16:25:08 à 17:10:58 | K49: =IF(A49=A50, C50, "") -> 2016-05-31 17:10:58 | L49: =IF(A49=A50, G50, "") -> 0.031828704 | M49: =IF(A49=A50, E49, "") -> 0.12581019 | N49: =IF(A49=A50, H50, "") -> BASE RAZEL BAGANGTE - BASE RAZEL BAGANGTE
... A61: BVT82 | B61: CARRIERE RAZEL LOGBADJECK | C61: 2016-05-31 16:34:30 | D61: 2016-05-31 17:14:30 | E61: =IFERROR(D61-C61, "") -> 0.027777778 | F61: Lundi | G61: =IF(A61=A60, C61-D60, "") -> 0.25763889 | H61: =IF(A61=A60, B60&" - "&B61, "") -> CARRIERE RAZEL LOGBADJECK - CARRIERE RAZEL LOGBADJECK | I61: =IF(F60='Données Hebdo'!A60, VLOOKUP(Feuil1!A61, 'Données Hebdo'!B:J, 8, FALSE), "") | J61: =IF(A61=A62, RIGHT(D61, 8)&" à "&RIGHT(C62, 8), "") -> 17:14:30 à 18:12:30 | K61: =IF(A61=A62, C62, "") -> 2016-05-31 18:12:30 | L61: =IF(A61=A62, G62, "") -> 0.040277778 | M61: =IF(A61=A62, E61, "") -> 0.027777778 | N61: =IF(A61=A62, H62, "") -> CARRIERE RAZEL LOGBADJECK - DEPOT RAZEL YASSA
A62: BVT82 | B62: DEPOT RAZEL YASSA | C62: 2016-05-31 18:12:30 | D62: 2016-06-01 05:40:59 | E62: =IFERROR(D62-C62, "") -> 0.47811343 | F62: Lundi | G62: =IF(A62=A61, C62-D61, "") -> 0.040277778 | H62: =IF(A62=A61, B61&" - "&B62, "") -> CARRIERE RAZEL LOGBADJECK - DEPOT RAZEL YASSA | I62: =IF(F61='Données Hebdo'!A61, VLOOKUP(Feuil1!A62, 'Données Hebdo'!B:J, 8, FALSE), "") | J62: =IF(A62=A36, RIGHT(D62, 8)&" à "&RIGHT(C36, 8), "") | K62: =IF(A62=A36, C36, "") | L62: =IF(A62=A36, G36, "") | M62: =IF(A62=A36, E62, "") | N62: =IF(A62=A36, H36, "")
A63: MV701 | B63: CARRIERE RAZEL NKOMETOU | C63: 2016-05-31 09:32:44 | D63: 2016-05-31 10:15:44 | E63: =IFERROR(D63-C63, "") -> 0.029861111 | F63: Lundi | G63: =IF(A63=A36, C63-D36, "") | H63: =IF(A63=A36, B36&" - "&B63, "") | I63: =IF(F36='Données Hebdo'!A63, VLOOKUP(Feuil1!A63, 'Données Hebdo'!B:J, 8, FALSE), "") | J63: =IF(A63=A64, RIGHT(D63, 8)&" à "&RIGHT(C64, 8), "") | K63: =IF(A63=A64, C64, "") | L63: =IF(A63=A64, G64, "") | M63: =IF(A63=A64, E63, "") | N63: =IF(A63=A64, H64, "")
A64: MV702 | B64: BASE RAZEL OLEMBE | C64: 2016-05-31 08:24:01 | D64: 2016-05-31 08:30:01 | E64: =IFERROR(D64-C64, "") -> 0.0041666667 | F64: Lundi | G64: =IF(A64=A63, C64-D63, "") | H64: =IF(A64=A63, B63&" - "&B64, "") | I64: =IF(F63='Données Hebdo'!A64, VLOOKUP(Feuil1!A64, 'Données Hebdo'!B:J, 8, FALSE), "") | J64: =IF(A64=A65, RIGHT(D64, 8)&" à "&RIGHT(C65, 8), "") -> 08:30:01 à 09:32:01 | K64: =IF(A64=A65, C65, "") -> 2016-05-31 09:32:01 | L64: =IF(A64=A65, G65, "") -> 0.043055556 | M64: =IF(A64=A65, E64, "") -> 0.0041666667 | N64: =IF(A64=A65, H65, "") -> BASE RAZEL OLEMBE - BASE RAZEL PADY 2
A65: MV702 | B65: BASE RAZEL PADY 2 | C65: 2016-05-31 09:32:01 | D65: 2016-05-31 09:48:22 | E65: =IFERROR(D65-C65, "") -> 0.011354167 | F65: Lundi | G65: =IF(A65=A64, C65-D64, "") -> 0.043055556 | H65: =IF(A65=A64, B64&" - "&B65, "") -> BASE RAZEL OLEMBE - BASE RAZEL PADY 2 | I65: =IF(F64='Données Hebdo'!A65, VLOOKUP(Feuil1!A65, 'Données Hebdo'!B:J, 8, FALSE), "") | J65: =IF(A65=A66, RIGHT(D65, 8)&" à "&RIGHT(C66, 8), "") | K65: =IF(A65=A66, C66, "") | L65: =IF(A65=A66, G66, "") | M65: =IF(A65=A66, E65, "") | N65: =IF(A65=A66, H66, "")
A66: BV706 | B66: BASE RAZEL BAGANGTE | C66: 2016-06-01 17:56:35 | D66: 2016-06-02 07:03:09 | E66: =IFERROR(D66-C66, "") -> 0.54622685 | F66: Lundi | G66: =IF(A66=A65, C66-D65, "") | H66: =IF(A66=A65, B65&" - "&B66, "") | I66: =IF(F65='Données Hebdo'!A66, VLOOKUP(Feuil1!A66, 'Données Hebdo'!B:J, 8, FALSE), "") | J66: =IF(A66=A67, RIGHT(D66, 8)&" à "&RIGHT(C67, 8), "") | K66: =IF(A66=A67, C67, "") | L66: =IF(A66=A67, G67, "") | M66: =IF(A66=A67, E66, "") | N66: =IF(A66=A67, H67, "")
A67: BV707 | B67: BASE RAZEL BAGANGTE | C67: 2016-06-01 16:35:00 | D67: 2016-06-02 06:41:03 | E67: =IFERROR(D67-C67, "") -> 0.58753472 | F67: Lundi | G67: =IF(A67=A66, C67-D66, "") | H67: =IF(A67=A66, B66&" - "&B67, "") | I67: =IF(F66='Données Hebdo'!A67, VLOOKUP(Feuil1!A67, 'Données Hebdo'!B:J, 8, FALSE), "") | J67: =IF(A67=A68, RIGHT(D67, 8)&" à "&RIGHT(C68, 8), "") | K67: =IF(A67=A68, C68, "") | L67: =IF(A67=A68, G68, "") | M67: =IF(A67=A68, E67, "") | N67: =IF(A67=A68, H68, "")
A68: BV711 | B68: BASE RAZEL BAGANGTE | C68: 2016-06-01 16:34:52 | D68: 2016-06-02 06:40:17 | E68: =IFERROR(D68-C68, "") -> 0.58709491 | F68: Lundi | G68: =IF(A68=A67, C68-D67, "") | H68: =IF(A68=A67, B67&" - "&B68, "") | I68: =IF(F67='Données Hebdo'!A68, VLOOKUP(Feuil1!A68, 'Données Hebdo'!B:J, 8, FALSE), "") | J68: =IF(A68=A69, RIGHT(D68, 8)&" à "&RIGHT(C69, 8), "") | K68: =IF(A68=A69, C69, "") | L68: =IF(A68=A69, G69, "") | M68: =IF(A68=A69, E68, "") | N68: =IF(A68=A69, H69, "")
A69: BVC74 | B69: BASE RAZEL BAGANGTE | C69: 2016-06-01 10:03:58 | D69: 2016-06-01 12:28:58 | E69: =IFERROR(D69-C69, "") -> 0.10069444 | F69: Lundi | G69: =IF(A69=A68, C69-D68, "") | H69: =IF(A69=A68, B68&" - "&B69, "") | I69: =IF(F68='Données Hebdo'!A69, VLOOKUP(Feuil1!A69, 'Données Hebdo'!B:J, 8, FALSE), "") | J69: =IF(A69=A70, RIGHT(D69, 8)&" à "&RIGHT(C70, 8), "") -> 12:28:58 à 15:19:58 | K69: =IF(A69=A70, C70, "") -> 2016-06-01 15:19:58 | L69: =IF(A69=A70, G70, "") -> 0.11875 | M69: =IF(A69=A70, E69, "") -> 0.10069444 | N69: =IF(A69=A70, H70, "") -> BASE RAZEL BAGANGTE - BASE RAZEL BAGANGTE
A70: BVC74 | B70: BASE RAZEL BAGANGTE | C70: 2016-06-01 15:19:58 | D70: 2016-06-02 07:34:57 | E70: =IFERROR(D70-C70, "") -> 0.67707176 | F70: Lundi | G70: =IF(A70=A69, C70-D69, "") -> 0.11875 | H70: =IF(A70=A69, B69&" - "&B70, "") -> BASE RAZEL BAGANGTE - BASE RAZEL BAGANGTE | I70: =IF(F69='Données Hebdo'!A70, VLOOKUP(Feuil1!A70, 'Données Hebdo'!B:J, 8, FALSE), "") | J70: =IF(A70=A71, RIGHT(D70, 8)&" à "&RIGHT(C71, 8), "") | K70: =IF(A70=A71, C71, "") | L70: =IF(A70=A71, G71, "") | M70: =IF(A70=A71, E70, "") | N70: =IF(A70=A71, H71, "")
A71: BVT39 | B71: BASE RAZEL PADY 2 | C71: 2016-06-01 09:12:56 | D71: 2016-06-01 09:13:56 | E71: =IFERROR(D71-C71, "") -> 0.00069444445 | F71: Lundi | G71: =IF(A71=A70, C71-D70, "") | H71: =IF(A71=A70, B70&" - "&B71, "") | I71: =IF(F70='Données Hebdo'!A71, VLOOKUP(Feuil1!A71, 'Données Hebdo'!B:J, 8, FALSE), "") | J71: =IF(A71=A72, RIGHT(D71, 8)&" à "&RIGHT(C72, 8), "") -> 09:13:56 à 11:18:58 | K71: =IF(A71=A72, C72, "") -> 2016-06-01 11:18:58 | L71: =IF(A71=A72, G72, "") -> 0.086828704 | M71: =IF(A71=A72, E71, "") -> 0.00069444445 | N71: =IF(A71=A72, H72, "") -> BASE RAZEL PADY 2 - BASE RAZEL PREFECTURE
A72: BVT39 | B72: BASE RAZEL PREFECTURE | C72: 2016-06-01 11:18:58 | D72: 2016-06-01 13:48:24 | E72: =IFERROR(D72-C72, "") -> 0.10377315 | F72: Lundi | G72: =IF(A72=A71, C72-D71, "") -> 0.086828704 | H72: =IF(A72=A71, B71&" - "&B72, "") -> BASE RAZEL PADY 2 - BASE RAZEL PREFECTURE | I72: =IF(F71='Données Hebdo'!A72, VLOOKUP(Feuil1!A72, 'Données Hebdo'!B:J, 8, FALSE), "") | J72: =IF(A72=A73, RIGHT(D72, 8)&" à "&RIGHT(C73, 8), "") -> 13:48:24 à 14:29:59 | K72: =IF(A72=A73, C73, "") -> 2016-06-01 14:29:59 | L72: =IF(A72=A73, G73, "") -> 0.028877315 | M72: =IF(A72=A73, E72, "") -> 0.10377315 | N72: =IF(A72=A73, H73, "") -> BASE RAZEL PREFECTURE - BASE RAZEL OLEMBE
A73: BVT39 | B73: BASE RAZEL OLEMBE | C73: 2016-06-01 14:29:59 | D73: 2016-06-01 16:26:42 | E73: =IFERROR(D73-C73, "") -> 0.081053241 | F73: Lundi | G73: =IF(A73=A72, C73-D72, "") -> 0.028877315 | H73: =IF(A73=A72, B72&" - "&B73, "") -> BASE RAZEL PREFECTURE - BASE RAZEL OLEMBE | I73: =IF(F72='Données Hebdo'!A73, VLOOKUP(Feuil1!A73, 'Données Hebdo'!B:J, 8, FALSE), "") | J73: =IF(A73=A74, RIGHT(D73, 8)&" à "&RIGHT(C74, 8), "") -> 16:26:42 à 17:01:05 | K73: =IF(A73=A74, C74, "") -> 2016-06-01 17:01:05 | L73: =IF(A73=A74, G74, "") -> 0.023877315 | M73: =IF(A73=A74, E73, "") -> 0.081053241 | N73: =IF(A73=A74, H74, "") -> BASE RAZEL OLEMBE - BASE RAZEL PREFECTURE
A74: BVT39 | B74: BASE RAZEL PREFECTURE | C74: 2016-06-01 17:01:05 | D74: 2016-06-02 07:16:55 | E74: =IFERROR(D74-C74, "") -> 0.5943287 | F74: Lundi | G74: =IF(A74=A73, C74-D73, "") -> 0.023877315 | H74: =IF(A74=A73, B73&" - "&B74, "") -> BASE RAZEL OLEMBE - BASE RAZEL PREFECTURE | I74: =IF(F73='Données Hebdo'!A74, VLOOKUP(Feuil1!A74, 'Données Hebdo'!B:J, 8, FALSE), "") | J74: =IF(A74=A75, RIGHT(D74, 8)&" à "&RIGHT(C75, 8), "") | K74: =IF(A74=A75, C75, "") | L74: =IF(A74=A75, G75, "") | M74: =IF(A74=A75, E74, "") | N74: =IF(A74=A75, H75, "")
...
